<?xml version="1.0" ?>
<robot name="Hiwonder" xmlns:xacro="http://www.ros.org/wiki/xacro">

<xacro:include filename="$(find Hiwonder_description)/urdf/materials.xacro" />
<xacro:include filename="$(find Hiwonder_description)/urdf/Hiwonder.trans" />
<xacro:include filename="$(find Hiwonder_description)/urdf/Hiwonder.gazebo" />
<link name="base_link">
  <inertial>
    <origin xyz="1.0914827906389602e-06 0.09260862084125268 0.03056402721165038" rpy="0 0 0"/>
    <mass value="1.5251096871562557"/>
    <inertia ixx="0.008261" iyy="0.002907" izz="0.009107" ixy="0.0" iyz="0.001105" ixz="-0.0"/>
  </inertial>
  <visual>
    <origin xyz="0 0 0" rpy="0 0 0"/>
    <geometry>
      <mesh filename="package://Hiwonder_description/meshes/base_link.stl" scale="0.001 0.001 0.001"/>
    </geometry>
    <material name="silver"/>
  </visual>
  <collision>
    <origin xyz="0 0 0" rpy="0 0 0"/>
    <geometry>
      <mesh filename="package://Hiwonder_description/meshes/base_link.stl" scale="0.001 0.001 0.001"/>
    </geometry>
  </collision>
</link>

<link name="second_link_1">
  <inertial>
    <origin xyz="0.0015155642244600214 1.7928644227976909e-06 0.024809430057861744" rpy="0 0 0"/>
    <mass value="0.37909012139587217"/>
    <inertia ixx="0.000161" iyy="0.00016" izz="0.000201" ixy="0.0" iyz="0.0" ixz="-6e-06"/>
  </inertial>
  <visual>
    <origin xyz="0.0 -0.056304 -0.060801" rpy="0 0 0"/>
    <geometry>
      <mesh filename="package://Hiwonder_description/meshes/second_link_1.stl" scale="0.001 0.001 0.001"/>
    </geometry>
    <material name="silver"/>
  </visual>
  <collision>
    <origin xyz="0.0 -0.056304 -0.060801" rpy="0 0 0"/>
    <geometry>
      <mesh filename="package://Hiwonder_description/meshes/second_link_1.stl" scale="0.001 0.001 0.001"/>
    </geometry>
  </collision>
</link>

<link name="sixth_link_1">
  <inertial>
    <origin xyz="0.00015608115480679387 0.04624085970692193 0.0051057604762696635" rpy="0 0 0"/>
    <mass value="0.5747761409814244"/>
    <inertia ixx="0.000539" iyy="0.000275" izz="0.000338" ixy="-1e-06" iyz="-5.5e-05" ixz="-1e-06"/>
  </inertial>
  <visual>
    <origin xyz="0.004904 -0.303181 -0.097772" rpy="0 0 0"/>
    <geometry>
      <mesh filename="package://Hiwonder_description/meshes/sixth_link_1.stl" scale="0.001 0.001 0.001"/>
    </geometry>
    <material name="silver"/>
  </visual>
  <collision>
    <origin xyz="0.004904 -0.303181 -0.097772" rpy="0 0 0"/>
    <geometry>
      <mesh filename="package://Hiwonder_description/meshes/sixth_link_1.stl" scale="0.001 0.001 0.001"/>
    </geometry>
  </collision>
</link>

<link name="fourth_link_1">
  <inertial>
    <origin xyz="0.029415116021796684 0.02350618639049401 2.928660555476248e-05" rpy="0 0 0"/>
    <mass value="0.29239025387829376"/>
    <inertia ixx="0.000208" iyy="8.1e-05" izz="0.000266" ixy="-2e-06" iyz="-0.0" ixz="0.0"/>
  </inertial>
  <visual>
    <origin xyz="0.02878 -0.150304 -0.095854" rpy="0 0 0"/>
    <geometry>
      <mesh filename="package://Hiwonder_description/meshes/fourth_link_1.stl" scale="0.001 0.001 0.001"/>
    </geometry>
    <material name="silver"/>
  </visual>
  <collision>
    <origin xyz="0.02878 -0.150304 -0.095854" rpy="0 0 0"/>
    <geometry>
      <mesh filename="package://Hiwonder_description/meshes/fourth_link_1.stl" scale="0.001 0.001 0.001"/>
    </geometry>
  </collision>
</link>

<link name="fifth_link_1">
  <inertial>
    <origin xyz="0.024821079126874524 0.019918646651746308 0.009994548839560524" rpy="0 0 0"/>
    <mass value="0.293803405398946"/>
    <inertia ixx="0.000201" iyy="0.000102" izz="0.000168" ixy="6e-06" iyz="1e-06" ixz="1e-06"/>
  </inertial>
  <visual>
    <origin xyz="0.03018 -0.238894 -0.095884" rpy="0 0 0"/>
    <geometry>
      <mesh filename="package://Hiwonder_description/meshes/fifth_link_1.stl" scale="0.001 0.001 0.001"/>
    </geometry>
    <material name="silver"/>
  </visual>
  <collision>
    <origin xyz="0.03018 -0.238894 -0.095884" rpy="0 0 0"/>
    <geometry>
      <mesh filename="package://Hiwonder_description/meshes/fifth_link_1.stl" scale="0.001 0.001 0.001"/>
    </geometry>
  </collision>
</link>

<link name="third_link_1">
  <inertial>
    <origin xyz="-0.027698779003945215 0.051975132993045764 2.647541288663957e-05" rpy="0 0 0"/>
    <mass value="0.162262457476611"/>
    <inertia ixx="0.000203" iyy="0.000102" izz="0.00029" ixy="-0.0" iyz="-0.0" ixz="0.0"/>
  </inertial>
  <visual>
    <origin xyz="-0.02722 -0.046304 -0.095801" rpy="0 0 0"/>
    <geometry>
      <mesh filename="package://Hiwonder_description/meshes/third_link_1.stl" scale="0.001 0.001 0.001"/>
    </geometry>
    <material name="silver"/>
  </visual>
  <collision>
    <origin xyz="-0.02722 -0.046304 -0.095801" rpy="0 0 0"/>
    <geometry>
      <mesh filename="package://Hiwonder_description/meshes/third_link_1.stl" scale="0.001 0.001 0.001"/>
    </geometry>
  </collision>
</link>

<link name="left_finger_1">
  <inertial>
    <origin xyz="0.10077586565386246 -0.2951398577015533 -0.024100390242242975" rpy="0 0 0"/>
    <mass value="0.016905829223014094"/>
    <inertia ixx="7e-06" iyy="5e-06" izz="6e-06" ixy="1e-06" iyz="2e-06" ixz="-0.0"/>
  </inertial>
  <visual>
    <origin xyz="0.102737 -0.696581 -0.092807" rpy="0 0 0"/>
    <geometry>
      <mesh filename="package://Hiwonder_description/meshes/left_finger_1.stl" scale="0.001 0.001 0.001"/>
    </geometry>
    <material name="silver"/>
  </visual>
  <collision>
    <origin xyz="0.102737 -0.696581 -0.092807" rpy="0 0 0"/>
    <geometry>
      <mesh filename="package://Hiwonder_description/meshes/left_finger_1.stl" scale="0.001 0.001 0.001"/>
    </geometry>
  </collision>
</link>

<link name="right_finger_1">
  <inertial>
    <origin xyz="0.09580963018641239 -0.2972024291150857 0.08107960390528858" rpy="0 0 0"/>
    <mass value="0.016905829223014094"/>
    <inertia ixx="7e-06" iyy="5e-06" izz="6e-06" ixy="-1e-06" iyz="-2e-06" ixz="-0.0"/>
  </inertial>
  <visual>
    <origin xyz="0.102838 -0.697104 -0.070113" rpy="0 0 0"/>
    <geometry>
      <mesh filename="package://Hiwonder_description/meshes/right_finger_1.stl" scale="0.001 0.001 0.001"/>
    </geometry>
    <material name="silver"/>
  </visual>
  <collision>
    <origin xyz="0.102838 -0.697104 -0.070113" rpy="0 0 0"/>
    <geometry>
      <mesh filename="package://Hiwonder_description/meshes/right_finger_1.stl" scale="0.001 0.001 0.001"/>
    </geometry>
  </collision>
</link>

<link name="left_silicone_1">
  <inertial>
    <origin xyz="4.687864967756108e-05 -0.00020343105991710297 0.0107648753930749" rpy="0 0 0"/>
    <mass value="0.01625853008781884"/>
    <inertia ixx="2e-06" iyy="6e-06" izz="5e-06" ixy="0.0" iyz="0.0" ixz="0.0"/>
  </inertial>
  <visual>
    <origin xyz="0.005817 -0.413386 -0.064354" rpy="0 0 0"/>
    <geometry>
      <mesh filename="package://Hiwonder_description/meshes/left_silicone_1.stl" scale="0.001 0.001 0.001"/>
    </geometry>
    <material name="silver"/>
  </visual>
  <collision>
    <origin xyz="0.005817 -0.413386 -0.064354" rpy="0 0 0"/>
    <geometry>
      <mesh filename="package://Hiwonder_description/meshes/left_silicone_1.stl" scale="0.001 0.001 0.001"/>
    </geometry>
  </collision>
</link>

<link name="right_ilicone_1">
  <inertial>
    <origin xyz="-4.7089655312079065e-05 0.00020383228202164316 -0.010764495822386339" rpy="0 0 0"/>
    <mass value="0.01625853008781884"/>
    <inertia ixx="2e-06" iyy="6e-06" izz="5e-06" ixy="0.0" iyz="0.0" ixz="0.0"/>
  </inertial>
  <visual>
    <origin xyz="0.003073 -0.411641 -0.155993" rpy="0 0 0"/>
    <geometry>
      <mesh filename="package://Hiwonder_description/meshes/right_ilicone_1.stl" scale="0.001 0.001 0.001"/>
    </geometry>
    <material name="silver"/>
  </visual>
  <collision>
    <origin xyz="0.003073 -0.411641 -0.155993" rpy="0 0 0"/>
    <geometry>
      <mesh filename="package://Hiwonder_description/meshes/right_ilicone_1.stl" scale="0.001 0.001 0.001"/>
    </geometry>
  </collision>
</link>

<joint name="Revolute 13" type="revolute">
  <origin xyz="0.0 0.056304 0.060801" rpy="0 0 0"/>
  <parent link="base_link"/>
  <child link="second_link_1"/>
  <axis xyz="0.0 0.0 -1.0"/>
  <limit upper="1.570796" lower="-1.570796" effort="100" velocity="100"/>
</joint>

<joint name="Revolute 19" type="revolute">
  <origin xyz="0.025276 0.064287 0.001888" rpy="0 0 0"/>
  <parent link="fifth_link_1"/>
  <child link="sixth_link_1"/>
  <axis xyz="-0.004192 -0.999812 -0.018919"/>
  <limit upper="3.141593" lower="0.0" effort="100" velocity="100"/>
</joint>

<joint name="Revolute 34" type="revolute">
  <origin xyz="-0.056 0.104 5.3e-05" rpy="0 0 0"/>
  <parent link="third_link_1"/>
  <child link="fourth_link_1"/>
  <axis xyz="1.0 0.0 0.0"/>
  <limit upper="3.141593" lower="0.0" effort="100" velocity="100"/>
</joint>

<joint name="Revolute 35" type="revolute">
  <origin xyz="-0.0014 0.08859 3e-05" rpy="0 0 0"/>
  <parent link="fourth_link_1"/>
  <child link="fifth_link_1"/>
  <axis xyz="1.0 0.0 0.0"/>
  <limit upper="1.570796" lower="0.0" effort="100" velocity="100"/>
</joint>

<joint name="Revolute 36" type="revolute">
  <origin xyz="0.02722 -0.01 0.035" rpy="0 0 0"/>
  <parent link="second_link_1"/>
  <child link="third_link_1"/>
  <axis xyz="1.0 0.0 0.0"/>
  <limit upper="3.141593" lower="0.0" effort="100" velocity="100"/>
</joint>

<joint name="Slider 37" type="prismatic">
  <origin xyz="-0.097833 0.3934 -0.004965" rpy="0 0 0"/>
  <parent link="sixth_link_1"/>
  <child link="left_finger_1"/>
  <axis xyz="-0.00438 0.018937 -0.999811"/>
  <limit upper="0.02" lower="-0.01" effort="100" velocity="100"/>
</joint>

<joint name="Slider 38" type="prismatic">
  <origin xyz="-0.097934 0.393923 -0.027659" rpy="0 0 0"/>
  <parent link="sixth_link_1"/>
  <child link="right_finger_1"/>
  <axis xyz="-0.00438 0.018937 -0.999811"/>
  <limit upper="0.01" lower="-0.02" effort="100" velocity="100"/>
</joint>

<joint name="Rigid 39" type="fixed">
  <origin xyz="0.09692 -0.283195 -0.028453" rpy="0 0 0"/>
  <parent link="left_finger_1"/>
  <child link="left_silicone_1"/>
</joint>

<joint name="Rigid 40" type="fixed">
  <origin xyz="0.099765 -0.285463 0.08588" rpy="0 0 0"/>
  <parent link="right_finger_1"/>
  <child link="right_ilicone_1"/>
</joint>

</robot>
