<?xml version="1.0" ?>
<!-- =================================================================================== -->
<!-- |    This document was autogenerated by xacro from urdf/Hiwonder.xacro            | -->
<!-- |    EDITING THIS FILE BY HAND IS NOT RECOMMENDED                                 | -->
<!-- =================================================================================== -->
<robot xmlns:xacro="http://www.ros.org/wiki/xacro" name="Hiwonder">
  <material name="silver">
    <color rgba="0.700 0.700 0.700 1.000"/>
  </material>
  <transmission name="Revolute 13_tran">
    <type>transmission_interface/SimpleTransmission</type>
    <joint name="Revolute 13">
      <hardwareInterface>hardware_interface/EffortJointInterface</hardwareInterface>
    </joint>
    <actuator name="Revolute 13_actr">
      <hardwareInterface>hardware_interface/EffortJointInterface</hardwareInterface>
      <mechanicalReduction>1</mechanicalReduction>
    </actuator>
  </transmission>
  <transmission name="Revolute 14_tran">
    <type>transmission_interface/SimpleTransmission</type>
    <joint name="Revolute 14">
      <hardwareInterface>hardware_interface/EffortJointInterface</hardwareInterface>
    </joint>
    <actuator name="Revolute 14_actr">
      <hardwareInterface>hardware_interface/EffortJointInterface</hardwareInterface>
      <mechanicalReduction>1</mechanicalReduction>
    </actuator>
  </transmission>
  <transmission name="Revolute 15_tran">
    <type>transmission_interface/SimpleTransmission</type>
    <joint name="Revolute 15">
      <hardwareInterface>hardware_interface/EffortJointInterface</hardwareInterface>
    </joint>
    <actuator name="Revolute 15_actr">
      <hardwareInterface>hardware_interface/EffortJointInterface</hardwareInterface>
      <mechanicalReduction>1</mechanicalReduction>
    </actuator>
  </transmission>
  <transmission name="Revolute 16_tran">
    <type>transmission_interface/SimpleTransmission</type>
    <joint name="Revolute 16">
      <hardwareInterface>hardware_interface/EffortJointInterface</hardwareInterface>
    </joint>
    <actuator name="Revolute 16_actr">
      <hardwareInterface>hardware_interface/EffortJointInterface</hardwareInterface>
      <mechanicalReduction>1</mechanicalReduction>
    </actuator>
  </transmission>
  <transmission name="Revolute 19_tran">
    <type>transmission_interface/SimpleTransmission</type>
    <joint name="Revolute 19">
      <hardwareInterface>hardware_interface/EffortJointInterface</hardwareInterface>
    </joint>
    <actuator name="Revolute 19_actr">
      <hardwareInterface>hardware_interface/EffortJointInterface</hardwareInterface>
      <mechanicalReduction>1</mechanicalReduction>
    </actuator>
  </transmission>
  <transmission name="Slider 29_tran">
    <type>transmission_interface/SimpleTransmission</type>
    <joint name="Slider 29">
      <hardwareInterface>hardware_interface/EffortJointInterface</hardwareInterface>
    </joint>
    <actuator name="Slider 29_actr">
      <hardwareInterface>hardware_interface/EffortJointInterface</hardwareInterface>
      <mechanicalReduction>1</mechanicalReduction>
    </actuator>
  </transmission>
  <transmission name="Slider 31_tran">
    <type>transmission_interface/SimpleTransmission</type>
    <joint name="Slider 31">
      <hardwareInterface>hardware_interface/EffortJointInterface</hardwareInterface>
    </joint>
    <actuator name="Slider 31_actr">
      <hardwareInterface>hardware_interface/EffortJointInterface</hardwareInterface>
      <mechanicalReduction>1</mechanicalReduction>
    </actuator>
  </transmission>
  <gazebo>
    <plugin name="control" filename="libgazebo_ros_control.so"/>
  </gazebo>
  <gazebo reference="base_link">
    <material>Gazebo/Silver</material>
    <mu1>0.2</mu1>
    <mu2>0.2</mu2>
    <selfCollide>true</selfCollide>
    <gravity>true</gravity>
  </gazebo>
  <gazebo reference="second_link_1">
    <material>Gazebo/Silver</material>
    <mu1>0.2</mu1>
    <mu2>0.2</mu2>
    <selfCollide>true</selfCollide>
  </gazebo>
  <gazebo reference="third_link_1">
    <material>Gazebo/Silver</material>
    <mu1>0.2</mu1>
    <mu2>0.2</mu2>
    <selfCollide>true</selfCollide>
  </gazebo>
  <gazebo reference="fourth_link_1">
    <material>Gazebo/Silver</material>
    <mu1>0.2</mu1>
    <mu2>0.2</mu2>
    <selfCollide>true</selfCollide>
  </gazebo>
  <gazebo reference="fifth_link_1">
    <material>Gazebo/Silver</material>
    <mu1>0.2</mu1>
    <mu2>0.2</mu2>
    <selfCollide>true</selfCollide>
  </gazebo>
  <gazebo reference="sixth_link_1">
    <material>Gazebo/Silver</material>
    <mu1>0.2</mu1>
    <mu2>0.2</mu2>
    <selfCollide>true</selfCollide>
  </gazebo>
  <gazebo reference="right_finger_1">
    <material>Gazebo/Silver</material>
    <mu1>0.2</mu1>
    <mu2>0.2</mu2>
    <selfCollide>true</selfCollide>
  </gazebo>
  <gazebo reference="left_finger_1">
    <material>Gazebo/Silver</material>
    <mu1>0.2</mu1>
    <mu2>0.2</mu2>
    <selfCollide>true</selfCollide>
  </gazebo>
  <link name="base_link">
    <inertial>
      <origin xyz="1.0914827906389602e-06 0.09260862084125268 0.03056402721165038" rpy="0 0 0"/>
      <mass value="1.5251096871562557"/>
      <inertia ixx="0.008261" iyy="0.002907" izz="0.009107" ixy="0.0" iyz="0.001105" ixz="-0.0"/>
    </inertial>
    <visual>
      <origin xyz="0 0 0" rpy="0 0 0"/>
      <geometry>
        <mesh filename="package://Hiwonder_description/meshes/base_link.stl" scale="0.001 0.001 0.001"/>
      </geometry>
      <material name="silver"/>
    </visual>
    <collision>
      <origin xyz="0 0 0" rpy="0 0 0"/>
      <geometry>
        <mesh filename="package://Hiwonder_description/meshes/base_link.stl" scale="0.001 0.001 0.001"/>
      </geometry>
    </collision>
  </link>
  <link name="second_link_1">
    <inertial>
      <origin xyz="0.0015155642244600231 1.7928644227699353e-06 0.024809430057861744" rpy="0 0 0"/>
      <mass value="0.37909012139587217"/>
      <inertia ixx="0.000161" iyy="0.00016" izz="0.000201" ixy="0.0" iyz="0.0" ixz="-6e-06"/>
    </inertial>
    <visual>
      <origin xyz="0.0 -0.056304 -0.060801" rpy="0 0 0"/>
      <geometry>
        <mesh filename="package://Hiwonder_description/meshes/second_link_1.stl" scale="0.001 0.001 0.001"/>
      </geometry>
      <material name="silver"/>
    </visual>
    <collision>
      <origin xyz="0.0 -0.056304 -0.060801" rpy="0 0 0"/>
      <geometry>
        <mesh filename="package://Hiwonder_description/meshes/second_link_1.stl" scale="0.001 0.001 0.001"/>
      </geometry>
    </collision>
  </link>
  <link name="third_link_1">
    <inertial>
      <origin xyz="-0.027698296621942956 0.04765413999012262 0.020748432672287473" rpy="0 0 0"/>
      <mass value="0.16226233466168985"/>
      <inertia ixx="0.000203" iyy="0.000132" izz="0.00026" ixy="-0.0" iyz="-6.9e-05" ixz="-0.0"/>
    </inertial>
    <visual>
      <origin xyz="-0.028042 -0.046304 -0.095801" rpy="0 0 0"/>
      <geometry>
        <mesh filename="package://Hiwonder_description/meshes/third_link_1.stl" scale="0.001 0.001 0.001"/>
      </geometry>
      <material name="silver"/>
    </visual>
    <collision>
      <origin xyz="-0.028042 -0.046304 -0.095801" rpy="0 0 0"/>
      <geometry>
        <mesh filename="package://Hiwonder_description/meshes/third_link_1.stl" scale="0.001 0.001 0.001"/>
      </geometry>
    </collision>
  </link>
  <link name="fourth_link_1">
    <inertial>
      <origin xyz="-0.02572686990818987 0.004053928250455058 0.023157892432834615" rpy="0 0 0"/>
      <mass value="0.2923899366437736"/>
      <inertia ixx="0.000208" iyy="0.00026" izz="8.7e-05" ixy="-0.0" iyz="-3.2e-05" ixz="-2e-06"/>
    </inertial>
    <visual>
      <origin xyz="-0.028042 -0.141658 -0.137318" rpy="0 0 0"/>
      <geometry>
        <mesh filename="package://Hiwonder_description/meshes/fourth_link_1.stl" scale="0.001 0.001 0.001"/>
      </geometry>
      <material name="silver"/>
    </visual>
    <collision>
      <origin xyz="-0.028042 -0.141658 -0.137318" rpy="0 0 0"/>
      <geometry>
        <mesh filename="package://Hiwonder_description/meshes/fourth_link_1.stl" scale="0.001 0.001 0.001"/>
      </geometry>
    </collision>
  </link>
  <link name="fifth_link_1">
    <inertial>
      <origin xyz="0.02482151135065362 -0.01754474473381723 0.013754851957438224" rpy="0 0 0"/>
      <mass value="0.29380221652800204"/>
      <inertia ixx="0.000201" iyy="0.000157" izz="0.000113" ixy="-4e-06" iyz="2.4e-05" ixz="5e-06"/>
    </inertial>
    <visual>
      <origin xyz="0.0285 -0.157021 -0.224566" rpy="0 0 0"/>
      <geometry>
        <mesh filename="package://Hiwonder_description/meshes/fifth_link_1.stl" scale="0.001 0.001 0.001"/>
      </geometry>
      <material name="silver"/>
    </visual>
    <collision>
      <origin xyz="0.0285 -0.157021 -0.224566" rpy="0 0 0"/>
      <geometry>
        <mesh filename="package://Hiwonder_description/meshes/fifth_link_1.stl" scale="0.001 0.001 0.001"/>
      </geometry>
    </collision>
  </link>
  <link name="sixth_link_1">
    <inertial>
      <origin xyz="-5.564917727016649e-05 -0.024329962527568846 0.039653341169548384" rpy="0 0 0"/>
      <mass value="0.5747761409814244"/>
      <inertia ixx="0.000539" iyy="0.000285" izz="0.000328" ixy="-9e-06" iyz="5.9e-05" ixz="-2e-06"/>
    </inertial>
    <visual>
      <origin xyz="0.003224 -0.127901 -0.28191" rpy="0 0 0"/>
      <geometry>
        <mesh filename="package://Hiwonder_description/meshes/sixth_link_1.stl" scale="0.001 0.001 0.001"/>
      </geometry>
      <material name="silver"/>
    </visual>
    <collision>
      <origin xyz="0.003224 -0.127901 -0.28191" rpy="0 0 0"/>
      <geometry>
        <mesh filename="package://Hiwonder_description/meshes/sixth_link_1.stl" scale="0.001 0.001 0.001"/>
      </geometry>
    </collision>
  </link>
  <link name="right_finger_1">
    <inertial>
      <origin xyz="0.3334698569050242 -0.00907267411723324 -0.01453310351807563" rpy="0 0 0"/>
      <mass value="0.07962832262347441"/>
      <inertia ixx="4.1e-05" iyy="3.8e-05" izz="2.4e-05" ixy="3e-06" iyz="-1.2e-05" ixz="1e-05"/>
    </inertial>
    <visual>
      <origin xyz="0.336601 -0.108453 -0.384364" rpy="0 0 0"/>
      <geometry>
        <mesh filename="package://Hiwonder_description/meshes/right_finger_1.stl" scale="0.001 0.001 0.001"/>
      </geometry>
      <material name="silver"/>
    </visual>
    <collision>
      <origin xyz="0.336601 -0.108453 -0.384364" rpy="0 0 0"/>
      <geometry>
        <mesh filename="package://Hiwonder_description/meshes/right_finger_1.stl" scale="0.001 0.001 0.001"/>
      </geometry>
    </collision>
  </link>
  <link name="left_finger_1">
    <inertial>
      <origin xyz="0.0021544872810023447 -0.02302381129656561 0.005335867881885781" rpy="0 0 0"/>
      <mass value="0.07506411850762539"/>
      <inertia ixx="3.9e-05" iyy="1.2e-05" izz="3.7e-05" ixy="-1e-06" iyz="3e-06" ixz="0.0"/>
    </inertial>
    <visual>
      <origin xyz="0.014763 -0.085594 -0.345323" rpy="0 0 0"/>
      <geometry>
        <mesh filename="package://Hiwonder_description/meshes/left_finger_1.stl" scale="0.001 0.001 0.001"/>
      </geometry>
      <material name="silver"/>
    </visual>
    <collision>
      <origin xyz="0.014763 -0.085594 -0.345323" rpy="0 0 0"/>
      <geometry>
        <mesh filename="package://Hiwonder_description/meshes/left_finger_1.stl" scale="0.001 0.001 0.001"/>
      </geometry>
    </collision>
  </link>
  <joint name="Revolute 13" type="revolute">
    <origin xyz="0.0 0.056304 0.060801" rpy="0 0 0"/>
    <parent link="base_link"/>
    <child link="second_link_1"/>
    <axis xyz="0.0 0.0 -1.0"/>
    <limit upper="1.570796" lower="-1.570796" effort="100" velocity="100"/>
  </joint>
  <joint name="Revolute 14" type="revolute">
    <origin xyz="0.028042 -0.01 0.035" rpy="0 0 0"/>
    <parent link="second_link_1"/>
    <child link="third_link_1"/>
    <axis xyz="-1.0 -0.0 -0.0"/>
    <limit upper="0.785398" lower="-2.094395" effort="100" velocity="100"/>
  </joint>
  <joint name="Revolute 15" type="revolute">
    <origin xyz="0.0 0.095354 0.041517" rpy="0 0 0"/>
    <parent link="third_link_1"/>
    <child link="fourth_link_1"/>
    <axis xyz="-1.0 -0.0 -0.0"/>
    <limit upper="2.879793" lower="-0.261799" effort="100" velocity="100"/>
  </joint>
  <joint name="Revolute 16" type="revolute">
    <origin xyz="-0.056542 0.015363 0.087248" rpy="0 0 0"/>
    <parent link="fourth_link_1"/>
    <child link="fifth_link_1"/>
    <axis xyz="1.0 0.0 0.0"/>
    <limit upper="0.698132" lower="-2.443461" effort="100" velocity="100"/>
  </joint>
  <joint name="Revolute 19" type="revolute">
    <origin xyz="0.025276 -0.02912 0.057344" rpy="0 0 0"/>
    <parent link="fifth_link_1"/>
    <child link="sixth_link_1"/>
    <axis xyz="-0.004192 0.443437 -0.896296"/>
    <limit upper="3.141593" lower="0.0" effort="100" velocity="100"/>
  </joint>
  <joint name="Slider 29" type="prismatic">
    <origin xyz="-0.333377 -0.019448 0.102454" rpy="0 0 0"/>
    <parent link="sixth_link_1"/>
    <child link="right_finger_1"/>
    <axis xyz="0.045686 0.895452 0.442806"/>
    <limit upper="0.01" lower="-0.01" effort="100" velocity="100"/>
  </joint>
  <joint name="Slider 31" type="prismatic">
    <origin xyz="-0.011539 -0.042307 0.063413" rpy="0 0 0"/>
    <parent link="sixth_link_1"/>
    <child link="left_finger_1"/>
    <axis xyz="0.045686 0.895452 0.442806"/>
    <limit upper="0.01" lower="-0.01" effort="100" velocity="100"/>
    <mimic joint="Slider 29" multiplier="-1.0" offset="0.0" />
  </joint>
</robot>
