<?xml version="1.0" ?>
<!-- =================================================================================== -->
<!-- |    This document was autogenerated by xacro from urdf/Hiwonder.xacro            | -->
<!-- |    EDITING THIS FILE BY HAND IS NOT RECOMMENDED                                 | -->
<!-- =================================================================================== -->
<robot xmlns:xacro="http://www.ros.org/wiki/xacro" name="Hiwonder">
  <material name="silver">
    <color rgba="0.700 0.700 0.700 1.000"/>
  </material>
  <transmission name="Revolute 13_tran">
    <type>transmission_interface/SimpleTransmission</type>
    <joint name="Revolute 13">
      <hardwareInterface>hardware_interface/EffortJointInterface</hardwareInterface>
    </joint>
    <actuator name="Revolute 13_actr">
      <hardwareInterface>hardware_interface/EffortJointInterface</hardwareInterface>
      <mechanicalReduction>1</mechanicalReduction>
    </actuator>
  </transmission>
  <transmission name="Revolute 14_tran">
    <type>transmission_interface/SimpleTransmission</type>
    <joint name="Revolute 14">
      <hardwareInterface>hardware_interface/EffortJointInterface</hardwareInterface>
    </joint>
    <actuator name="Revolute 14_actr">
      <hardwareInterface>hardware_interface/EffortJointInterface</hardwareInterface>
      <mechanicalReduction>1</mechanicalReduction>
    </actuator>
  </transmission>
  <transmission name="Revolute 15_tran">
    <type>transmission_interface/SimpleTransmission</type>
    <joint name="Revolute 15">
      <hardwareInterface>hardware_interface/EffortJointInterface</hardwareInterface>
    </joint>
    <actuator name="Revolute 15_actr">
      <hardwareInterface>hardware_interface/EffortJointInterface</hardwareInterface>
      <mechanicalReduction>1</mechanicalReduction>
    </actuator>
  </transmission>
  <transmission name="Revolute 16_tran">
    <type>transmission_interface/SimpleTransmission</type>
    <joint name="Revolute 16">
      <hardwareInterface>hardware_interface/EffortJointInterface</hardwareInterface>
    </joint>
    <actuator name="Revolute 16_actr">
      <hardwareInterface>hardware_interface/EffortJointInterface</hardwareInterface>
      <mechanicalReduction>1</mechanicalReduction>
    </actuator>
  </transmission>
  <transmission name="Revolute 19_tran">
    <type>transmission_interface/SimpleTransmission</type>
    <joint name="Revolute 19">
      <hardwareInterface>hardware_interface/EffortJointInterface</hardwareInterface>
    </joint>
    <actuator name="Revolute 19_actr">
      <hardwareInterface>hardware_interface/EffortJointInterface</hardwareInterface>
      <mechanicalReduction>1</mechanicalReduction>
    </actuator>
  </transmission>
  <transmission name="Slider 20_tran">
    <type>transmission_interface/SimpleTransmission</type>
    <joint name="Slider 20">
      <hardwareInterface>hardware_interface/EffortJointInterface</hardwareInterface>
    </joint>
    <actuator name="Slider 20_actr">
      <hardwareInterface>hardware_interface/EffortJointInterface</hardwareInterface>
      <mechanicalReduction>1</mechanicalReduction>
    </actuator>
  </transmission>
  <transmission name="Slider 21_tran">
    <type>transmission_interface/SimpleTransmission</type>
    <joint name="Slider 21">
      <hardwareInterface>hardware_interface/EffortJointInterface</hardwareInterface>
    </joint>
    <actuator name="Slider 21_actr">
      <hardwareInterface>hardware_interface/EffortJointInterface</hardwareInterface>
      <mechanicalReduction>1</mechanicalReduction>
    </actuator>
  </transmission>
  <transmission name="Revolute 22_tran">
    <type>transmission_interface/SimpleTransmission</type>
    <joint name="Revolute 22">
      <hardwareInterface>hardware_interface/EffortJointInterface</hardwareInterface>
    </joint>
    <actuator name="Revolute 22_actr">
      <hardwareInterface>hardware_interface/EffortJointInterface</hardwareInterface>
      <mechanicalReduction>1</mechanicalReduction>
    </actuator>
  </transmission>
  <gazebo>
    <plugin name="control" filename="libgazebo_ros_control.so"/>
  </gazebo>
  <gazebo reference="base_link">
    <material>Gazebo/Silver</material>
    <mu1>0.2</mu1>
    <mu2>0.2</mu2>
    <selfCollide>true</selfCollide>
    <gravity>true</gravity>
  </gazebo>
  <gazebo reference="second_link_1">
    <material>Gazebo/Silver</material>
    <mu1>0.2</mu1>
    <mu2>0.2</mu2>
    <selfCollide>true</selfCollide>
  </gazebo>
  <gazebo reference="third_link_1">
    <material>Gazebo/Silver</material>
    <mu1>0.2</mu1>
    <mu2>0.2</mu2>
    <selfCollide>true</selfCollide>
  </gazebo>
  <gazebo reference="fourth_link_1">
    <material>Gazebo/Silver</material>
    <mu1>0.2</mu1>
    <mu2>0.2</mu2>
    <selfCollide>true</selfCollide>
  </gazebo>
  <gazebo reference="fifth_link_1">
    <material>Gazebo/Silver</material>
    <mu1>0.2</mu1>
    <mu2>0.2</mu2>
    <selfCollide>true</selfCollide>
  </gazebo>
  <gazebo reference="sixth_link_1">
    <material>Gazebo/Silver</material>
    <mu1>0.2</mu1>
    <mu2>0.2</mu2>
    <selfCollide>true</selfCollide>
  </gazebo>
  <gazebo reference="left_finger_1">
    <material>Gazebo/Silver</material>
    <mu1>0.2</mu1>
    <mu2>0.2</mu2>
    <selfCollide>true</selfCollide>
  </gazebo>
  <gazebo reference="right_finger_1">
    <material>Gazebo/Silver</material>
    <mu1>0.2</mu1>
    <mu2>0.2</mu2>
    <selfCollide>true</selfCollide>
  </gazebo>
  <gazebo reference="gear_link_1">
    <material>Gazebo/Silver</material>
    <mu1>0.2</mu1>
    <mu2>0.2</mu2>
    <selfCollide>true</selfCollide>
  </gazebo>
  <link name="base_link">
    <inertial>
      <origin xyz="1.0914827906389602e-06 0.09260862084125268 0.03056402721165038" rpy="0 0 0"/>
      <mass value="1.5251096871562557"/>
      <inertia ixx="0.008261" iyy="0.002907" izz="0.009107" ixy="0.0" iyz="0.001105" ixz="-0.0"/>
    </inertial>
    <visual>
      <origin xyz="0 0 0" rpy="0 0 0"/>
      <geometry>
        <mesh filename="package://Hiwonder_description/meshes/base_link.stl" scale="0.001 0.001 0.001"/>
      </geometry>
      <material name="silver"/>
    </visual>
    <collision>
      <origin xyz="0 0 0" rpy="0 0 0"/>
      <geometry>
        <mesh filename="package://Hiwonder_description/meshes/base_link.stl" scale="0.001 0.001 0.001"/>
      </geometry>
    </collision>
  </link>
  <link name="second_link_1">
    <inertial>
      <origin xyz="0.001515476232598548 -1.6684843491224233e-05 0.02480943005786166" rpy="0 0 0"/>
      <mass value="0.37909012139587217"/>
      <inertia ixx="0.000161" iyy="0.00016" izz="0.000201" ixy="0.0" iyz="0.0" ixz="-6e-06"/>
    </inertial>
    <visual>
      <origin xyz="0.0 -0.056304 -0.060801" rpy="0 0 0"/>
      <geometry>
        <mesh filename="package://Hiwonder_description/meshes/second_link_1.stl" scale="0.001 0.001 0.001"/>
      </geometry>
      <material name="silver"/>
    </visual>
    <collision>
      <origin xyz="0.0 -0.056304 -0.060801" rpy="0 0 0"/>
      <geometry>
        <mesh filename="package://Hiwonder_description/meshes/second_link_1.stl" scale="0.001 0.001 0.001"/>
      </geometry>
    </collision>
  </link>
  <link name="third_link_1">
    <inertial>
      <origin xyz="-0.027343180150573892 0.029293876913652088 0.04316047625280414" rpy="0 0 0"/>
      <mass value="0.16226233466168985"/>
      <inertia ixx="0.000203" iyy="0.000231" izz="0.00016" ixy="0.0" iyz="-8.7e-05" ixz="-1e-06"/>
    </inertial>
    <visual>
      <origin xyz="-0.027918 -0.045963 -0.095801" rpy="0 0 0"/>
      <geometry>
        <mesh filename="package://Hiwonder_description/meshes/third_link_1.stl" scale="0.001 0.001 0.001"/>
      </geometry>
      <material name="silver"/>
    </visual>
    <collision>
      <origin xyz="-0.027918 -0.045963 -0.095801" rpy="0 0 0"/>
      <geometry>
        <mesh filename="package://Hiwonder_description/meshes/third_link_1.stl" scale="0.001 0.001 0.001"/>
      </geometry>
    </collision>
  </link>
  <link name="fourth_link_1">
    <inertial>
      <origin xyz="-0.025886175644017836 -0.012863720404565696 0.019469646301894933" rpy="0 0 0"/>
      <mass value="0.2923899366437736"/>
      <inertia ixx="0.000208" iyy="0.000208" izz="0.000139" ixy="1e-06" iyz="8.6e-05" ixz="-1e-06"/>
    </inertial>
    <visual>
      <origin xyz="-0.028625 -0.103903 -0.182163" rpy="0 0 0"/>
      <geometry>
        <mesh filename="package://Hiwonder_description/meshes/fourth_link_1.stl" scale="0.001 0.001 0.001"/>
      </geometry>
      <material name="silver"/>
    </visual>
    <collision>
      <origin xyz="-0.028625 -0.103903 -0.182163" rpy="0 0 0"/>
      <geometry>
        <mesh filename="package://Hiwonder_description/meshes/fourth_link_1.stl" scale="0.001 0.001 0.001"/>
      </geometry>
    </collision>
  </link>
  <link name="fifth_link_1">
    <inertial>
      <origin xyz="0.024573606883266846 -0.020492170669535084 -0.009450750798881968" rpy="0 0 0"/>
      <mass value="0.29380221652800204"/>
      <inertia ixx="0.000201" iyy="0.000102" izz="0.000168" ixy="-8e-06" iyz="3e-06" ixz="-1e-06"/>
    </inertial>
    <visual>
      <origin xyz="0.028518 -0.05501 -0.255576" rpy="0 0 0"/>
      <geometry>
        <mesh filename="package://Hiwonder_description/meshes/fifth_link_1.stl" scale="0.001 0.001 0.001"/>
      </geometry>
      <material name="silver"/>
    </visual>
    <collision>
      <origin xyz="0.028518 -0.05501 -0.255576" rpy="0 0 0"/>
      <geometry>
        <mesh filename="package://Hiwonder_description/meshes/fifth_link_1.stl" scale="0.001 0.001 0.001"/>
      </geometry>
    </collision>
  </link>
  <link name="sixth_link_1">
    <inertial>
      <origin xyz="-0.00040907580167635384 -0.046363022962390074 -0.0038289785318220693" rpy="0 0 0"/>
      <mass value="0.5747761409814244"/>
      <inertia ixx="0.000539" iyy="0.000272" izz="0.000341" ixy="-3e-06" iyz="-5.3e-05" ixz="0.0"/>
    </inertial>
    <visual>
      <origin xyz="0.004028 0.009607 -0.255463" rpy="0 0 0"/>
      <geometry>
        <mesh filename="package://Hiwonder_description/meshes/sixth_link_1.stl" scale="0.001 0.001 0.001"/>
      </geometry>
      <material name="silver"/>
    </visual>
    <collision>
      <origin xyz="0.004028 0.009607 -0.255463" rpy="0 0 0"/>
      <geometry>
        <mesh filename="package://Hiwonder_description/meshes/sixth_link_1.stl" scale="0.001 0.001 0.001"/>
      </geometry>
    </collision>
  </link>
  <link name="left_finger_1">
    <inertial>
      <origin xyz="0.22614187622313073 -0.16382465810915833 -0.07528218342616169" rpy="0 0 0"/>
      <mass value="0.07506411850762539"/>
      <inertia ixx="3.9e-05" iyy="2.9e-05" izz="2e-05" ixy="-0.0" iyz="-1.2e-05" ixz="0.0"/>
    </inertial>
    <visual>
      <origin xyz="0.239188 -0.06338 -0.290008" rpy="0 0 0"/>
      <geometry>
        <mesh filename="package://Hiwonder_description/meshes/left_finger_1.stl" scale="0.001 0.001 0.001"/>
      </geometry>
      <material name="silver"/>
    </visual>
    <collision>
      <origin xyz="0.239188 -0.06338 -0.290008" rpy="0 0 0"/>
      <geometry>
        <mesh filename="package://Hiwonder_description/meshes/left_finger_1.stl" scale="0.001 0.001 0.001"/>
      </geometry>
    </collision>
  </link>
  <link name="right_finger_1">
    <inertial>
      <origin xyz="0.23353711603941524 -0.16423216885509756 0.009285417328035783" rpy="0 0 0"/>
      <mass value="0.07962832262347441"/>
      <inertia ixx="4e-05" iyy="3.6e-05" izz="2.7e-05" ixy="-8e-06" iyz="1.2e-05" ixz="8e-06"/>
    </inertial>
    <visual>
      <origin xyz="0.239287 -0.063365 -0.267308" rpy="0 0 0"/>
      <geometry>
        <mesh filename="package://Hiwonder_description/meshes/right_finger_1.stl" scale="0.001 0.001 0.001"/>
      </geometry>
      <material name="silver"/>
    </visual>
    <collision>
      <origin xyz="0.239287 -0.063365 -0.267308" rpy="0 0 0"/>
      <geometry>
        <mesh filename="package://Hiwonder_description/meshes/right_finger_1.stl" scale="0.001 0.001 0.001"/>
      </geometry>
    </collision>
  </link>
  <link name="gear_link_1">
    <inertial>
      <origin xyz="-6.661216082451751e-05 -0.008319512177334093 7.260586570295713e-05" rpy="0 0 0"/>
      <mass value="0.025254124812982604"/>
      <inertia ixx="2e-06" iyy="1e-06" izz="2e-06" ixy="-0.0" iyz="0.0" ixz="0.0"/>
    </inertial>
    <visual>
      <origin xyz="0.004496 0.068042 -0.245637" rpy="0 0 0"/>
      <geometry>
        <mesh filename="package://Hiwonder_description/meshes/gear_link_1.stl" scale="0.001 0.001 0.001"/>
      </geometry>
      <material name="silver"/>
    </visual>
    <collision>
      <origin xyz="0.004496 0.068042 -0.245637" rpy="0 0 0"/>
      <geometry>
        <mesh filename="package://Hiwonder_description/meshes/gear_link_1.stl" scale="0.001 0.001 0.001"/>
      </geometry>
    </collision>
  </link>
  <joint name="Revolute 13" type="revolute">
    <origin xyz="0.0 0.056304 0.060801" rpy="0 0 0"/>
    <parent link="base_link"/>
    <child link="second_link_1"/>
    <axis xyz="0.0 0.0 -1.0"/>
    <limit upper="1.570796" lower="-1.570796" effort="100" velocity="100"/>
  </joint>
  <joint name="Revolute 14" type="revolute">
    <origin xyz="0.027918 -0.010341 0.035" rpy="0 0 0"/>
    <parent link="second_link_1"/>
    <child link="third_link_1"/>
    <axis xyz="-0.999926 0.012192 -0.0"/>
    <limit upper="0.785398" lower="-2.094395" effort="100" velocity="100"/>
  </joint>
  <joint name="Revolute 15" type="revolute">
    <origin xyz="0.000707 0.05794 0.086362" rpy="0 0 0"/>
    <parent link="third_link_1"/>
    <child link="fourth_link_1"/>
    <axis xyz="-0.999926 0.012192 -0.0"/>
    <limit upper="2.879793" lower="-0.261799" effort="100" velocity="100"/>
  </joint>
  <joint name="Revolute 16" type="revolute">
    <origin xyz="-0.057143 -0.048893 0.073413" rpy="0 0 0"/>
    <parent link="fourth_link_1"/>
    <child link="fifth_link_1"/>
    <axis xyz="0.999926 -0.012192 0.0"/>
    <limit upper="0.698132" lower="-2.443461" effort="100" velocity="100"/>
  </joint>
  <joint name="Revolute 19" type="continuous">
    <origin xyz="0.02449 -0.064617 -0.000113" rpy="0 0 0"/>
    <parent link="fifth_link_1"/>
    <child link="sixth_link_1"/>
    <axis xyz="0.008 0.99993 -0.008671"/>
  </joint>
  <joint name="Slider 20" type="prismatic">
    <origin xyz="-0.23516 0.072987 0.034545" rpy="0 0 0"/>
    <parent link="sixth_link_1"/>
    <child link="left_finger_1"/>
    <axis xyz="-0.004274 0.008705 0.999953"/>
    <limit upper="0.015" lower="-0.015" effort="100" velocity="100"/>
  </joint>
  <joint name="Slider 21" type="prismatic">
    <origin xyz="-0.235259 0.072972 0.011845" rpy="0 0 0"/>
    <parent link="sixth_link_1"/>
    <child link="right_finger_1"/>
    <axis xyz="-0.004274 0.008705 0.999953"/>
    <limit upper="0.015" lower="-0.015" effort="100" velocity="100"/>
  </joint>
  <joint name="Revolute 22" type="revolute">
    <origin xyz="-0.000468 -0.058435 -0.009826" rpy="0 0 0"/>
    <parent link="sixth_link_1"/>
    <child link="gear_link_1"/>
    <axis xyz="0.008 0.99993 -0.008671"/>
    <limit upper="5.585054" lower="0.872665" effort="100" velocity="100"/>
  </joint>
</robot>
