<?xml version="1.0"?>
<robot name="Hiwonder">

  <link name="base_link">
    <visual>
      <origin xyz="0 0 0" rpy="0 0 0" />
      <geometry>
        <mesh filename="meshes/base_link.stl" scale="0.001 0.001 0.001" />
      </geometry>
      <material name="base_link_mat">
        <color rgba="0.69804314 0.69804314 0.69804314 1.00000000"/>
      </material>
    </visual>
    <collision>
      <origin xyz="0 0.12 0.03" rpy="0 0 0" />
      <geometry>
        <box size="0.11 0.26 0.11" />
      </geometry>
    </collision>
    <inertial>
      <origin xyz="0.0000011 0.0926086 0.030564" rpy="0 0 0" />
      <mass value="1.5251097" />
      <inertia ixx="0.008261" ixy="0" ixz="0" iyy="0.002907" iyz="0.001105" izz="0.009107" />
    </inertial>
  </link>

  <link name="second_link_1">
    <visual>
      <origin xyz="0 -0.056304 -0.060801" rpy="0 0 0" />
      <geometry>
        <mesh filename="meshes/second_link_1.stl" scale="0.001 0.001 0.001" />
      </geometry>
      <material name="second_link_1_mat">
        <color rgba="0.69804314 0.69804314 0.69804314 1.00000000"/>
      </material>
    </visual>
    <inertial>
      <origin xyz="0.0015156 0.0000018 0.0248094" rpy="0 0 0" />
      <mass value="0.3790901" />
      <inertia ixx="0.000161" ixy="0" ixz="-0.000006" iyy="0.00016" iyz="0" izz="0.000201" />
    </inertial>
  </link>

  <link name="sixth_link_1">
    <visual>
      <origin xyz="0.004904 -0.303181 -0.097772" rpy="0 0 0" />
      <geometry>
        <mesh filename="meshes/sixth_link_1.stl" scale="0.001 0.001 0.001" />
      </geometry>
      <material name="sixth_link_1_mat">
        <color rgba="0.69804314 0.69804314 0.69804314 1.00000000"/>
      </material>
    </visual>
    <collision>
      <origin xyz="0.0003134 0.0429652 0.0117462" rpy="0 0 0" />
      <geometry>
        <box size="0.0311505 0.0860716 0.0855082" />
      </geometry>
    </collision>
    <inertial>
      <origin xyz="0.0001561 0.0462409 0.0051058" rpy="0 0 0" />
      <mass value="0.5747761" />
      <inertia ixx="0.000539" ixy="-0.000001" ixz="-0.000001" iyy="0.000275" iyz="-0.000055" izz="0.000338" />
    </inertial>
  </link>

  <link name="fourth_link_1">
    <visual>
      <origin xyz="0.02878 -0.150304 -0.095854" rpy="0 0 0" />
      <geometry>
        <mesh filename="meshes/fourth_link_1.stl" scale="0.001 0.001 0.001" />
      </geometry>
      <material name="fourth_link_1_mat">
        <color rgba="0.69804314 0.69804314 0.69804314 1.00000000"/>
      </material>
    </visual>
    <collision>
      <origin xyz="0.03 0.03 0" rpy="0 0 0" />
      <geometry>
        <box size="0.06 0.09 0.03" />
      </geometry>
    </collision>
    <inertial>
      <origin xyz="0.0294151 0.0235062 0.0000293" rpy="0 0 0" />
      <mass value="0.2923903" />
      <inertia ixx="0.000208" ixy="-0.000002" ixz="0" iyy="0.000081" iyz="0" izz="0.000266" />
    </inertial>
  </link>

  <link name="fifth_link_1">
    <visual>
      <origin xyz="0.03018 -0.238894 -0.095884" rpy="0 0 0" />
      <geometry>
        <mesh filename="meshes/fifth_link_1.stl" scale="0.001 0.001 0.001" />
      </geometry>
      <material name="fifth_link_1_mat">
        <color rgba="0.69804314 0.69804314 0.69804314 1.00000000"/>
      </material>
    </visual>
    <collision>
      <origin xyz="0.03 0.03 0.01" rpy="0 0 0" />
      <geometry>
        <box size="0.08 0.07 0.07" />
      </geometry>
    </collision>
    <inertial>
      <origin xyz="0.0248211 0.0199186 0.0099945" rpy="0 0 0" />
      <mass value="0.2938034" />
      <inertia ixx="0.000201" ixy="0.000006" ixz="0.000001" iyy="0.000102" iyz="0.000001" izz="0.000168" />
    </inertial>
  </link>

  <link name="third_link_1">
    <visual>
      <origin xyz="-0.02722 -0.046304 -0.095801" rpy="0 0 0" />
      <geometry>
        <mesh filename="meshes/third_link_1.stl" scale="0.001 0.001 0.001" />
      </geometry>
      <material name="third_link_1_mat">
        <color rgba="0.69804314 0.69804314 0.69804314 1.00000000"/>
      </material>
    </visual>
    <collision>
      <origin xyz="-0.028 0.042 0.0000265" rpy="0 0 0" />
      <geometry>
        <box size="0.0602 0.089 0.03" />
      </geometry>
    </collision>
    <inertial>
      <origin xyz="-0.0276988 0.0519751 0.0000265" rpy="0 0 0" />
      <mass value="0.1622625" />
      <inertia ixx="0.000203" ixy="0" ixz="0" iyy="0.000102" iyz="0" izz="0.00029" />
    </inertial>
  </link>

  <link name="left_finger_1">
    <visual>
      <origin xyz="0.102737 -0.696581 -0.092807" rpy="0 0 0" />
      <geometry>
        <mesh filename="meshes/left_finger_1.stl" scale="0.001 0.001 0.001" />
      </geometry>
      <material name="left_finger_1_mat">
        <color rgba="0.69804314 0.69804314 0.69804314 1.00000000"/>
      </material>
    </visual>
    <collision>
      <origin xyz="0.102737 -0.696581 -0.092807" rpy="0 0 0" />
      <geometry>
        <mesh filename="meshes/left_finger_1.stl" scale="0.001 0.001 0.001" />
      </geometry>
    </collision>
    <inertial>
      <origin xyz="0.1007759 -0.2951399 -0.0241004" rpy="0 0 0" />
      <mass value="0.0169058" />
      <inertia ixx="0.000007" ixy="0.000001" ixz="0" iyy="0.000005" iyz="0.000002" izz="0.000006" />
    </inertial>
  </link>

  <link name="right_finger_1">
    <visual>
      <origin xyz="0.102838 -0.697104 -0.070113" rpy="0 0 0" />
      <geometry>
        <mesh filename="meshes/right_finger_1.stl" scale="0.001 0.001 0.001" />
      </geometry>
      <material name="right_finger_1_mat">
        <color rgba="0.69804314 0.69804314 0.69804314 1.00000000"/>
      </material>
    </visual>
    <collision>
      <origin xyz="0.102838 -0.697104 -0.070113" rpy="0 0 0" />
      <geometry>
        <mesh filename="meshes/right_finger_1.stl" scale="0.001 0.001 0.001" />
      </geometry>
    </collision>
    <inertial>
      <origin xyz="0.0958096 -0.2972024 0.0810796" rpy="0 0 0" />
      <mass value="0.0169058" />
      <inertia ixx="0.000007" ixy="-0.000001" ixz="0" iyy="0.000005" iyz="-0.000002" izz="0.000006" />
    </inertial>
  </link>

  <link name="left_silicone_1">
    <visual>
      <origin xyz="0.005817 -0.413386 -0.064354" rpy="0 0 0" />
      <geometry>
        <mesh filename="meshes/left_silicone_1.stl" scale="0.001 0.001 0.001" />
      </geometry>
      <material name="left_silicone_1_mat">
        <color rgba="0.69804314 0.69804314 0.69804314 1.00000000"/>
      </material>
    </visual>
    <collision>
      <origin xyz="0.005817 -0.413386 -0.064354" rpy="0 0 0" />
      <geometry>
        <mesh filename="meshes/left_silicone_1.stl" scale="0.001 0.001 0.001" />
      </geometry>
    </collision>
    <inertial>
      <origin xyz="0.0000469 -0.0002034 0.0107649" rpy="0 0 0" />
      <mass value="0.0162585" />
      <inertia ixx="0.000002" ixy="0" ixz="0" iyy="0.000006" iyz="0" izz="0.000005" />
    </inertial>
  </link>

  <link name="right_ilicone_1">
    <visual>
      <origin xyz="0.003073 -0.411641 -0.155993" rpy="0 0 0" />
      <geometry>
        <mesh filename="meshes/right_ilicone_1.stl" scale="0.001 0.001 0.001" />
      </geometry>
      <material name="right_ilicone_1_mat">
        <color rgba="0.69804314 0.69804314 0.69804314 1.00000000"/>
      </material>
    </visual>
    <collision>
      <origin xyz="0.003073 -0.411641 -0.155993" rpy="0 0 0" />
      <geometry>
        <mesh filename="meshes/right_ilicone_1.stl" scale="0.001 0.001 0.001" />
      </geometry>
    </collision>
    <inertial>
      <origin xyz="-0.0000471 0.0002038 -0.0107645" rpy="0 0 0" />
      <mass value="0.0162585" />
      <inertia ixx="0.000002" ixy="0" ixz="0" iyy="0.000006" iyz="0" izz="0.000005" />
    </inertial>
  </link>

  <joint name="Revolute 13" type="revolute">
    <parent link="base_link" />
    <child link="second_link_1" />
    <origin xyz="0 0.056304 0.060801" rpy="0 0 -1.5707963" />
    <axis xyz="0 0 1" />
    <limit lower="0" upper="3.1416" effort="100" velocity="100" />
  </joint>

  <joint name="Revolute 19" type="revolute">
    <parent link="fifth_link_1" />
    <child link="sixth_link_1" />
    <origin xyz="0.025276 0.064287 0.001888" rpy="0 1.5707963 0" />
    <axis xyz="0 1 0" />
    <limit lower="0" upper="3.141593" effort="100" velocity="100" />
  </joint>

  <joint name="Revolute 34" type="revolute">
    <parent link="third_link_1" />
    <child link="fourth_link_1" />
    <origin xyz="-0.056 0.104 0.000053" rpy="1.5707963 0 0" />
    <axis xyz="-1 0 0" />
    <limit lower="0" upper="1.57079" effort="100" velocity="100" />
  </joint>

  <joint name="Revolute 35" type="revolute">
    <parent link="fourth_link_1" />
    <child link="fifth_link_1" />
    <origin xyz="-0.0014 0.08859 0.00003" rpy="1.5707963 0 0" />
    <axis xyz="-1 0 0" />
    <limit lower="0" upper="1.570796" effort="100" velocity="100" />
  </joint>

  <joint name="Revolute 36" type="revolute">
    <parent link="second_link_1" />
    <child link="third_link_1" />
    <origin xyz="0.02722 -0.01 0.035" rpy="0 0 0" />
    <axis xyz="1 0 0" />
    <limit lower="0" upper="3.141593" effort="100" velocity="100" />
  </joint>

  <joint name="Slider 37" type="prismatic">
    <parent link="sixth_link_1" />
    <child link="left_finger_1" />
    <origin xyz="-0.097833 0.3934 -0.004965" rpy="0 0 0" />
    <axis xyz="-0.00438 0.018937 -0.999811" />
    <limit lower="-0.01" upper="0.02" effort="100" velocity="100" />
  </joint>

  <joint name="Slider 38" type="prismatic">
    <parent link="sixth_link_1" />
    <child link="right_finger_1" />
    <origin xyz="-0.097934 0.393923 -0.027659" rpy="0 0 0" />
    <axis xyz="-0.00438 0.018937 -0.999811" />
    <limit lower="-0.02" upper="0.01" effort="100" velocity="100" />
  </joint>

  <joint name="Rigid 39" type="fixed">
    <parent link="left_finger_1" />
    <child link="left_silicone_1" />
    <origin xyz="0.09692 -0.283195 -0.028453" rpy="0 0 0" />
  </joint>

  <joint name="Rigid 40" type="fixed">
    <parent link="right_finger_1" />
    <child link="right_ilicone_1" />
    <origin xyz="0.099765 -0.285463 0.08588" rpy="0 0 0" />
  </joint>

</robot>