<?xml version="1.0"?>
<robot name="Hiwonder">

    <link name="base_link">
      <visual>
        <origin xyz="0 0 0" rpy="0 0 0" />
        <geometry>
          <mesh filename="meshes/base_link.stl" scale="0.001 0.001 0.001" />
        </geometry>
        <material name="silver">
          <color rgba="0.70000000 0.70000000 0.70000000 1.00000000"/>
        </material>
      </visual>
      <collision>
        <origin xyz="0 0.055 0.041623" rpy="0 0 0" />
        <geometry>
          <cylinder radius="0.057168" length="0.073" />
        </geometry>
      </collision>
      <inertial>
        <origin xyz="0.0000011 0.0926086 0.030564" rpy="0 0 0" />
        <mass value="1.5251097" />
        <inertia ixx="0.008261" ixy="0" ixz="0" iyy="0.002907" iyz="0.001105" izz="0.009107" />
      </inertial>
    </link>

    <link name="second_link_1">
      <visual>
        <origin xyz="0 -0.056304 -0.060801" rpy="0 0 0" />
        <geometry>
          <mesh filename="meshes/second_link_1.stl" scale="0.001 0.001 0.001" />
        </geometry>
        <material name="silver">
          <color rgba="0.70000000 0.70000000 0.70000000 1.00000000"/>
        </material>
      </visual>
      <inertial>
        <origin xyz="0.0015156 0.0000018 0.0248094" rpy="0 0 0" />
        <mass value="0.3790901" />
        <inertia ixx="0.000161" ixy="0" ixz="-0.000006" iyy="0.00016" iyz="0" izz="0.000201" />
      </inertial>
    </link>

    <link name="sixth_link_1">
      <visual>
        <origin xyz="0.004904 -0.303181 -0.097772" rpy="0 0 0" />
        <geometry>
          <mesh filename="meshes/sixth_link_1.stl" scale="0.001 0.001 0.001" />
        </geometry>
        <material name="silver">
          <color rgba="0.70000000 0.70000000 0.70000000 1.00000000"/>
        </material>
      </visual>
      <collision>
        <origin xyz="-0.005096 0.046819 0.002228" rpy="0 0 0" />
        <geometry>
          <box size="0.02 0.08 0.08" />
        </geometry>
      </collision>
      <inertial>
        <origin xyz="0.0001561 0.0464351 -0.0051604" rpy="0 0 0" />
        <mass value="0.5747761" />
        <inertia ixx="0.000539" ixy="-0.000001" ixz="-0.000001" iyy="0.000275" iyz="-0.000053" izz="0.000338" />
      </inertial>
    </link>

    <link name="fourth_link_1">
      <visual>
        <origin xyz="0.02878 -0.150304 -0.095854" rpy="0 0 0" />
        <geometry>
          <mesh filename="meshes/fourth_link_1.stl" scale="0.001 0.001 0.001" />
        </geometry>
        <material name="silver">
          <color rgba="0.70000000 0.70000000 0.70000000 1.00000000"/>
        </material>
      </visual>
      <collision>
        <origin xyz="0.02878 0.039696 0" rpy="0 0 0" />
        <geometry>
          <box size="0.06 0.04 0.020001" />
        </geometry>
      </collision>
      <inertial>
        <origin xyz="0.0294151 0.0235062 0.0000293" rpy="0 0 0" />
        <mass value="0.2923903" />
        <inertia ixx="0.000208" ixy="-0.000002" ixz="0" iyy="0.000081" iyz="0" izz="0.000266" />
      </inertial>
    </link>

    <link name="fifth_link_1">
      <visual>
        <origin xyz="0.03018 -0.238894 -0.095884" rpy="0 0 0" />
        <geometry>
          <mesh filename="meshes/fifth_link_1.stl" scale="0.001 0.001 0.001" />
        </geometry>
        <material name="silver">
          <color rgba="0.70000000 0.70000000 0.70000000 1.00000000"/>
        </material>
      </visual>
      <collision>
        <origin xyz="0.02018 0.025 0.014116" rpy="0 0 0" />
        <geometry>
          <box size="0.04 0.07 0.06" />
        </geometry>
      </collision>
      <inertial>
        <origin xyz="0.0248211 0.0199186 0.0099945" rpy="0 0 0" />
        <mass value="0.2938034" />
        <inertia ixx="0.000201" ixy="0.000006" ixz="0.000001" iyy="0.000102" iyz="0.000001" izz="0.000168" />
      </inertial>
    </link>

    <link name="third_link_1">
      <visual>
        <origin xyz="-0.02722 -0.046304 -0.095801" rpy="0 0 0" />
        <geometry>
          <mesh filename="meshes/third_link_1.stl" scale="0.001 0.001 0.001" />
        </geometry>
        <material name="silver">
          <color rgba="0.70000000 0.70000000 0.70000000 1.00000000"/>
        </material>
      </visual>
      <collision>
        <origin xyz="-0.02722 0.053696 0" rpy="0 0 0" />
        <geometry>
          <box size="0.06 0.11 0.02" />
        </geometry>
      </collision>
      <inertial>
        <origin xyz="-0.0276988 0.0519751 0.0000265" rpy="0 0 0" />
        <mass value="0.1622625" />
        <inertia ixx="0.000203" ixy="0" ixz="0" iyy="0.000102" iyz="0" izz="0.00029" />
      </inertial>
    </link>

    <link name="left_finger_1">
      <visual>
        <origin xyz="0.092407 -0.696929 -0.082481" rpy="0 0 0" />
        <geometry>
          <mesh filename="meshes/left_finger_1.stl" scale="0.001 0.001 0.001" />
        </geometry>
        <material name="silver">
          <color rgba="0.70000000 0.70000000 0.70000000 1.00000000"/>
        </material>
      </visual>
      <inertial>
        <origin xyz="0.0904459 -0.2952924 -0.0241035" rpy="0 0 0" />
        <mass value="0.0169058" />
        <inertia ixx="0.000007" ixy="0.000001" ixz="0" iyy="0.000005" iyz="0.000002" izz="0.000006" />
      </inertial>
    </link>

    <link name="right_finger_1">
      <visual>
        <origin xyz="0.092508 -0.697452 -0.059787" rpy="0 0 0" />
        <geometry>
          <mesh filename="meshes/right_finger_1.stl" scale="0.001 0.001 0.001" />
        </geometry>
        <material name="silver">
          <color rgba="0.70000000 0.70000000 0.70000000 1.00000000"/>
        </material>
      </visual>
      <inertial>
        <origin xyz="0.0854796 -0.297355 0.0810765" rpy="0 0 0" />
        <mass value="0.0169058" />
        <inertia ixx="0.000007" ixy="-0.000001" ixz="0" iyy="0.000005" iyz="-0.000002" izz="0.000006" />
      </inertial>
    </link>

    <link name="left_silicone_1">
      <visual>
        <origin xyz="0.005817 -0.413582 -0.054025" rpy="0 0 0" />
        <geometry>
          <mesh filename="meshes/left_silicone_1.stl" scale="0.001 0.001 0.001" />
        </geometry>
        <material name="silver">
          <color rgba="0.70000000 0.70000000 0.70000000 1.00000000"/>
        </material>
      </visual>
      <collision>
        <origin xyz="0.005817 -0.413582 -0.054025" rpy="0 0 0" />
        <geometry>
          <mesh filename="meshes/left_silicone_1.stl" scale="0.001 0.001 0.001" />
        </geometry>
      </collision>
      <inertial>
        <origin xyz="0.0000469 -0.000204 0.0107647" rpy="0 0 0" />
        <mass value="0.0162585" />
        <inertia ixx="0.000002" ixy="0" ixz="0" iyy="0.000006" iyz="0" izz="0.000005" />
      </inertial>
    </link>

    <link name="right_ilicone_1">
      <visual>
        <origin xyz="0.003073 -0.411836 -0.145664" rpy="0 0 0" />
        <geometry>
          <mesh filename="meshes/right_ilicone_1.stl" scale="0.001 0.001 0.001" />
        </geometry>
        <material name="silver">
          <color rgba="0.70000000 0.70000000 0.70000000 1.00000000"/>
        </material>
      </visual>
      <collision>
        <origin xyz="0.003073 -0.411836 -0.145664" rpy="0 0 0" />
        <geometry>
          <mesh filename="meshes/right_ilicone_1.stl" scale="0.001 0.001 0.001" />
        </geometry>
      </collision>
      <inertial>
        <origin xyz="-0.0000471 0.0002043 -0.0107646" rpy="0 0 0" />
        <mass value="0.0162585" />
        <inertia ixx="0.000002" ixy="0" ixz="0" iyy="0.000006" iyz="0" izz="0.000005" />
      </inertial>
    </link>

  <joint name="Revolute 13" type="revolute">
    <parent link="base_link" />
    <child link="second_link_1" />
    <origin xyz="0 0.056304 0.060801" rpy="0 0 0" />
    <axis xyz="0 0 1" />
    <limit lower="-1.570796" upper="1.570796" effort="100" velocity="100" />
  </joint>

  <joint name="Revolute 19" type="revolute">
    <parent link="fifth_link_1" />
    <child link="sixth_link_1" />
    <origin xyz="0.025276 0.064287 0.001888" rpy="0 1.5707963 0" />
    <axis xyz="0 1 0" />
    <limit lower="0" upper="3.141593" effort="100" velocity="100" />
  </joint>

  <joint name="Revolute 34" type="revolute">
    <parent link="third_link_1" />
    <child link="fourth_link_1" />
    <origin xyz="-0.056 0.104 0.000053" rpy="1.5707963 0 0" />
    <axis xyz="-1 0 0" />
    <limit lower="0" upper="1.57079" effort="100" velocity="100" />
  </joint>

  <joint name="Revolute 35" type="revolute">
    <parent link="fourth_link_1" />
    <child link="fifth_link_1" />
    <origin xyz="-0.0014 0.08859 0.00003" rpy="1.5707963 0 0" />
    <axis xyz="-1 0 0" />
    <limit lower="0" upper="1.570796" effort="100" velocity="100" />
  </joint>

  <joint name="Revolute 36" type="revolute">
    <parent link="second_link_1" />
    <child link="third_link_1" />
    <origin xyz="0.02722 -0.01 0.035" rpy="0 0 0" />
    <axis xyz="1 0 0" />
    <limit lower="0" upper="3.141593" effort="100" velocity="100" />
  </joint>

  <joint name="Slider 37" type="prismatic">
    <parent link="sixth_link_1" />
    <child link="left_finger_1" />
    <origin xyz="-0.087503 0.393748 -0.015291" rpy="0 0 0" />
    <axis xyz="-0.00438 0.018937 -0.999811" />
    <limit lower="-0.01" upper="0.02" effort="100" velocity="100" />
  </joint>

  <joint name="Slider 38" type="prismatic">
    <parent link="sixth_link_1" />
    <child link="right_finger_1" />
    <origin xyz="-0.087604 0.394271 -0.037985" rpy="0 0 0" />
    <axis xyz="-0.00438 0.018937 -0.999811" />
    <limit lower="-0.02" upper="0.01" effort="100" velocity="100" />
    <mimic joint="Slider 37" multiplier="-1" offset="0" />
  </joint>

  <joint name="Rigid 39" type="fixed">
    <parent link="left_finger_1" />
    <child link="left_silicone_1" />
    <origin xyz="0.08659 -0.283347 -0.028456" rpy="0 0 0" />
  </joint>

  <joint name="Rigid 40" type="fixed">
    <parent link="right_finger_1" />
    <child link="right_ilicone_1" />
    <origin xyz="0.089435 -0.285616 0.085877" rpy="0 0 0" />
  </joint>

</robot>